{"trial_id": "1", "hyperparameters": {"space": [{"class_name": "Int", "config": {"name": "units", "default": null, "conditions": [], "min_value": 50, "max_value": 500, "step": 50, "sampling": "linear"}}, {"class_name": "Float", "config": {"name": "dropout", "default": 0.0, "conditions": [], "min_value": 0.0, "max_value": 0.5, "step": 0.1, "sampling": "linear"}}], "values": {"units": 150, "dropout": 0.30000000000000004}}, "metrics": {"metrics": {}}, "score": null, "best_step": 0, "status": "FAILED", "message": "Traceback (most recent call last):\n  File \"C:\\Users\\Yahan\\anaconda3\\lib\\site-packages\\keras_tuner\\src\\engine\\base_tuner.py\", line 274, in _try_run_and_update_trial\n    self._run_and_update_trial(trial, *fit_args, **fit_kwargs)\n  File \"C:\\Users\\Yahan\\anaconda3\\lib\\site-packages\\keras_tuner\\src\\engine\\base_tuner.py\", line 239, in _run_and_update_trial\n    results = self.run_trial(trial, *fit_args, **fit_kwargs)\n  File \"C:\\Users\\Yahan\\anaconda3\\lib\\site-packages\\keras_tuner\\src\\engine\\tuner.py\", line 314, in run_trial\n    obj_value = self._build_and_fit_model(trial, *args, **copied_kwargs)\n  File \"C:\\Users\\Yahan\\anaconda3\\lib\\site-packages\\keras_tuner\\src\\engine\\tuner.py\", line 233, in _build_and_fit_model\n    results = self.hypermodel.fit(hp, model, *args, **kwargs)\n  File \"C:\\Users\\Yahan\\anaconda3\\lib\\site-packages\\keras_tuner\\src\\engine\\hypermodel.py\", line 149, in fit\n    return model.fit(*args, **kwargs)\n  File \"C:\\Users\\Yahan\\anaconda3\\lib\\site-packages\\keras\\src\\utils\\traceback_utils.py\", line 70, in error_handler\n    raise e.with_traceback(filtered_tb) from None\n  File \"C:\\Users\\Yahan\\AppData\\Local\\Temp\\__autograph_generated_filelov5rwe2.py\", line 15, in tf__train_function\n    retval_ = ag__.converted_call(ag__.ld(step_function), (ag__.ld(self), ag__.ld(iterator)), None, fscope)\nValueError: in user code:\n\n    File \"C:\\Users\\Yahan\\anaconda3\\lib\\site-packages\\keras\\src\\engine\\training.py\", line 1401, in train_function  *\n        return step_function(self, iterator)\n    File \"C:\\Users\\Yahan\\anaconda3\\lib\\site-packages\\keras\\src\\engine\\training.py\", line 1384, in step_function  **\n        outputs = model.distribute_strategy.run(run_step, args=(data,))\n    File \"C:\\Users\\Yahan\\anaconda3\\lib\\site-packages\\keras\\src\\engine\\training.py\", line 1373, in run_step  **\n        outputs = model.train_step(data)\n    File \"C:\\Users\\Yahan\\anaconda3\\lib\\site-packages\\keras\\src\\engine\\training.py\", line 1150, in train_step\n        y_pred = self(x, training=True)\n    File \"C:\\Users\\Yahan\\anaconda3\\lib\\site-packages\\keras\\src\\utils\\traceback_utils.py\", line 70, in error_handler\n        raise e.with_traceback(filtered_tb) from None\n    File \"C:\\Users\\Yahan\\anaconda3\\lib\\site-packages\\keras\\src\\engine\\input_spec.py\", line 298, in assert_input_compatibility\n        raise ValueError(\n\n    ValueError: Input 0 of layer \"sequential\" is incompatible with the layer: expected shape=(None, 24, 17), found shape=(None, 24, 19)\n\n"}